Workbook

Sheet How to use
A1: Galactic Conquest: Project Bible
A3: This one file holds the names, events, tech, commanders, art specs, prompt templates, assets, and audio for the game. It pairs with BUILD_BRIEF.md version 4. The coding session reads it directly, or from a CSV export of each tab.
A5: WHAT TO EDIT
A6: Cultures: one row per culture (two per species). Describe how the culture sounds so generated names stay on style.
A7: Names: your hand-picked names. One name per row. These are always used first.
A8: Syllables: the building blocks the game remixes when a category runs out of hand-picked names.
A9: Categories: which kinds of names exist and whether the game may remix them. Pre-filled with suggestions; change freely.
A10: Rejected: names the generator produced that you never want to see again.
A12: CONVENTIONS
A13: Grey italic rows are examples showing the format. Delete or overwrite them.
A14: Shaded cells are for you to fill in. Dropdowns are on the category, position, and yes/no columns.
A15: Spell species and culture names exactly the same everywhere; the game matches on that text.
... A34: Commanders: the pool of commander types. Each time you found a fleet, four are offered, drawn from this pool, with names generated from your culture lists.

Sheet Cultures
A1: Species | B1: Culture | C1: Sound palette (sounds this culture favors) | D1: Sounds to avoid | E1: Look and feel notes | F1: Flavor notes for advisor dialogue
A2: Ploidun | B2: Orr (example) | C2: soft vowels; v, sh, n, l; names often end in -a or -is | D2: k, x, double consonants | E2: rounded hulls, flowing robes | F2: famously stubborn; diplomacy advisor groans about them

Sheet Categories
A1: Category | B1: Remix allowed (Y/N) | C1: Min syllables | D1: Max syllables | E1: What it's for
A2: given name | B2: Y | C2: 2 | D2: 3 | E2: First names for advisors, commanders, generals, merchants, envoys
A3: family name | B3: Y | C3: 1 | D3: 3 | E3: Surnames, clan or house names
A4: planet | B4: Y | C4: 2 | D4: 3 | E4: Planet names
A5: star system | B5: Y | C5: 1 | D5: 2 | E5: Star and system names
A6: sector | B6: Y | C6: 2 | D6: 3 | E6: Galaxy sector names
A7: point of interest | B7: Y | C7: 2 | D7: 3 | E7: Ruins, nebulae, stations, anomalies
A8: ship name | B8: N | E8: Capital ship names; best as words or phrases (Unbroken Vow, Kethis Dawn)
A9: faction word | B9: N | E9: Words for faction names (Hierarchy, Concern, Ascendancy); combined with a place name

Sheet Names
A1: Species | B1: Culture | C1: Category | D1: Name | E1: Pronunciation (optional) | F1: Notes
A2: Ploidun | B2: Orr (example) | C2: given name | D2: Vashenna | E2: VAH-shen-ah

Sheet Syllables
A1: Species | B1: Culture | C1: Position (start / middle / end) | D1: Syllable | E1: Used for (people / places / both) | F1: Notes
A2: Ploidun | B2: Orr (example) | C2: start | D2: Va | E2: both

Sheet Rejected
A1: Name | B1: Species | C1: Culture | D1: Why (optional)
A2: Vashshkis | B2: Ploidun | C2: Orr (example) | D2: unpronounceable

Sheet Events
A1: Event shape | B1: Trigger (what must be happening in the galaxy) | C1: Actors (filled in from the game) | D1: Delivered by (advisor) | E1: Choices (2 or 3) | F1: Consequences | G1: Follow-up (later event, if any) | H1: Cooldown before it can repeat | I1: Phrasing variants / notes
A2: Resource shortage (example) | B2: A rival has under 20% of a resource it needs, usually because a lane it trades through is blocked by war | C2: the short rival; the resource; the blocked lane; the warring faction | D2: Trade | E2: 1. Sell to them at a premium 2. Offer it in exchange for a treaty 3. Refuse and tip off their enemy | F2: 1. Credits now, relations up slightly 2. Treaty signed 3. Their enemy's relations up, theirs down if they find out | G2: If 3: chance they discover the leak 30 to 60 minutes later | H2: 2 hours of play | I2: Vary by rival temperament: an honorable rival asks politely, a treacherous one threatens

Sheet Commanders
A1: Commander type | B1: Hire cost (credits) | C1: Ongoing pay (credits per 10 min of play) | D1: Perk 1 | E1: Perk 2 | F1: Drawback (optional) | G1: Unlocks battle plan variant | H1: Notes
A2: Siege Veteran (example) | B2: 500 | C2: 40 | D2: +10% damage against orbital defenses | E2: Ground regiments land 20% faster | F2: Fleet moves 10% slower | G2: Siege | H2: Grey row is an example; overwrite it

Sheet Tech
A1: Track | B1: Level | C1: Slot | D1: Unlock name | E1: Suggested type | F1: Type | G1: What it does | H1: Research cost override | I1: Research cost | J1: Strength override | K1: Strength needed | L1: Notes
A2: Military | B2: 1 | C2: 1 | E2: New gear | I2: =IF(H2<>"",H2,IF(D2="","",ROUND('Tech budget'!$B$5*'Tech budget'!$B$6^(B2-1),0))) | K2: =IF(J2<>"",J2,IF(D2="","",ROUND('Tech budget'!$B$7*'Tech budget'!$B$8^(B2-1),0)))
A3: Military | B3: 1 | C3: 2 | I3: =IF(H3<>"",H3,IF(D3="","",ROUND('Tech budget'!$B$5*'Tech budget'!$B$6^(B3-1),0))) | K3: =IF(J3<>"",J3,IF(D3="","",ROUND('Tech budget'!$B$7*'Tech budget'!$B$8^(B3-1),0)))
A4: Military | B4: 2 | C4: 1 | E4: Stat buff | I4: =IF(H4<>"",H4,IF(D4="","",ROUND('Tech budget'!$B$5*'Tech budget'!$B$6^(B4-1),0))) | K4: =IF(J4<>"",J4,IF(D4="","",ROUND('Tech budget'!$B$7*'Tech budget'!$B$8^(B4-1),0)))
A5: Military | B5: 2 | C5: 2 | E5: Stat buff | I5: =IF(H5<>"",H5,IF(D5="","",ROUND('Tech budget'!$B$5*'Tech budget'!$B$6^(B5-1),0))) | K5: =IF(J5<>"",J5,IF(D5="","",ROUND('Tech budget'!$B$7*'Tech budget'!$B$8^(B5-1),0)))
A6: Military | B6: 3 | C6: 1 | E6: New gear | I6: =IF(H6<>"",H6,IF(D6="","",ROUND('Tech budget'!$B$5*'Tech budget'!$B$6^(B6-1),0))) | K6: =IF(J6<>"",J6,IF(D6="","",ROUND('Tech budget'!$B$7*'Tech budget'!$B$8^(B6-1),0)))
A7: Military | B7: 3 | C7: 2 | I7: =IF(H7<>"",H7,IF(D7="","",ROUND('Tech budget'!$B$5*'Tech budget'!$B$6^(B7-1),0))) | K7: =IF(J7<>"",J7,IF(D7="","",ROUND('Tech budget'!$B$7*'Tech budget'!$B$8^(B7-1),0)))
A8: Military | B8: 4 | C8: 1 | E8: Stat buff | I8: =IF(H8<>"",H8,IF(D8="","",ROUND('Tech budget'!$B$5*'Tech budget'!$B$6^(B8-1),0))) | K8: =IF(J8<>"",J8,IF(D8="","",ROUND('Tech budget'!$B$7*'Tech budget'!$B$8^(B8-1),0)))
A9: Military | B9: 4 | C9: 2 | E9: Stat buff | I9: =IF(H9<>"",H9,IF(D9="","",ROUND('Tech budget'!$B$5*'Tech budget'!$B$6^(B9-1),0))) | K9: =IF(J9<>"",J9,IF(D9="","",ROUND('Tech budget'!$B$7*'Tech budget'!$B$8^(B9-1),0)))
A10: Military | B10: 5 | C10: 1 | E10: New gear | I10: =IF(H10<>"",H10,IF(D10="","",ROUND('Tech budget'!$B$5*'Tech budget'!$B$6^(B10-1),0))) | K10: =IF(J10<>"",J10,IF(D10="","",ROUND('Tech budget'!$B$7*'Tech budget'!$B$8^(B10-1),0)))
A11: Military | B11: 5 | C11: 2 | I11: =IF(H11<>"",H11,IF(D11="","",ROUND('Tech budget'!$B$5*'Tech budget'!$B$6^(B11-1),0))) | K11: =IF(J11<>"",J11,IF(D11="","",ROUND('Tech budget'!$B$7*'Tech budget'!$B$8^(B11-1),0)))
A12: Military | B12: 6 | C12: 1 | E12: Stat buff | I12: =IF(H12<>"",H12,IF(D12="","",ROUND('Tech budget'!$B$5*'Tech budget'!$B$6^(B12-1),0))) | K12: =IF(J12<>"",J12,IF(D12="","",ROUND('Tech budget'!$B$7*'Tech budget'!$B$8^(B12-1),0)))
A13: Military | B13: 6 | C13: 2 | E13: Stat buff | I13: =IF(H13<>"",H13,IF(D13="","",ROUND('Tech budget'!$B$5*'Tech budget'!$B$6^(B13-1),0))) | K13: =IF(J13<>"",J13,IF(D13="","",ROUND('Tech budget'!$B$7*'Tech budget'!$B$8^(B13-1),0)))
A14: Military | B14: 7 | C14: 1 | E14: New gear | I14: =IF(H14<>"",H14,IF(D14="","",ROUND('Tech budget'!$B$5*'Tech budget'!$B$6^(B14-1),0))) | K14: =IF(J14<>"",J14,IF(D14="","",ROUND('Tech budget'!$B$7*'Tech budget'!$B$8^(B14-1),0)))
A15: Military | B15: 7 | C15: 2 | I15: =IF(H15<>"",H15,IF(D15="","",ROUND('Tech budget'!$B$5*'Tech budget'!$B$6^(B15-1),0))) | K15: =IF(J15<>"",J15,IF(D15="","",ROUND('Tech budget'!$B$7*'Tech budget'!$B$8^(B15-1),0)))
A16: Military | B16: 8 | C16: 1 | E16: Stat buff | I16: =IF(H16<>"",H16,IF(D16="","",ROUND('Tech budget'!$B$5*'Tech budget'!$B$6^(B16-1),0))) | K16: =IF(J16<>"",J16,IF(D16="","",ROUND('Tech budget'!$B$7*'Tech budget'!$B$8^(B16-1),0)))
A17: Military | B17: 8 | C17: 2 | E17: Stat buff | I17: =IF(H17<>"",H17,IF(D17="","",ROUND('Tech budget'!$B$5*'Tech budget'!$B$6^(B17-1),0))) | K17: =IF(J17<>"",J17,IF(D17="","",ROUND('Tech budget'!$B$7*'Tech budget'!$B$8^(B17-1),0)))
A18: Military | B18: 9 | C18: 1 | E18: New gear | I18: =IF(H18<>"",H18,IF(D18="","",ROUND('Tech budget'!$B$5*'Tech budget'!$B$6^(B18-1),0))) | K18: =IF(J18<>"",J18,IF(D18="","",ROUND('Tech budget'!$B$7*'Tech budget'!$B$8^(B18-1),0)))
A19: Military | B19: 9 | C19: 2 | I19: =IF(H19<>"",H19,IF(D19="","",ROUND('Tech budget'!$B$5*'Tech budget'!$B$6^(B19-1),0))) | K19: =IF(J19<>"",J19,IF(D19="","",ROUND('Tech budget'!$B$7*'Tech budget'!$B$8^(B19-1),0)))
A20: Military | B20: 10 | C20: 1 | E20: Stat buff | I20: =IF(H20<>"",H20,IF(D20="","",ROUND('Tech budget'!$B$5*'Tech budget'!$B$6^(B20-1),0))) | K20: =IF(J20<>"",J20,IF(D20="","",ROUND('Tech budget'!$B$7*'Tech budget'!$B$8^(B20-1),0)))
A21: Military | B21: 10 | C21: 2 | E21: Stat buff | I21: =IF(H21<>"",H21,IF(D21="","",ROUND('Tech budget'!$B$5*'Tech budget'!$B$6^(B21-1),0))) | K21: =IF(J21<>"",J21,IF(D21="","",ROUND('Tech budget'!$B$7*'Tech budget'!$B$8^(B21-1),0)))
A22: Military | B22: 11 | C22: 1 | E22: New gear | I22: =IF(H22<>"",H22,IF(D22="","",ROUND('Tech budget'!$B$5*'Tech budget'!$B$6^(B22-1),0))) | K22: =IF(J22<>"",J22,IF(D22="","",ROUND('Tech budget'!$B$7*'Tech budget'!$B$8^(B22-1),0)))
A23: Military | B23: 11 | C23: 2 | I23: =IF(H23<>"",H23,IF(D23="","",ROUND('Tech budget'!$B$5*'Tech budget'!$B$6^(B23-1),0))) | K23: =IF(J23<>"",J23,IF(D23="","",ROUND('Tech budget'!$B$7*'Tech budget'!$B$8^(B23-1),0)))
A24: Military | B24: 12 | C24: 1 | E24: Stat buff | I24: =IF(H24<>"",H24,IF(D24="","",ROUND('Tech budget'!$B$5*'Tech budget'!$B$6^(B24-1),0))) | K24: =IF(J24<>"",J24,IF(D24="","",ROUND('Tech budget'!$B$7*'Tech budget'!$B$8^(B24-1),0)))
A25: Military | B25: 12 | C25: 2 | E25: Stat buff | I25: =IF(H25<>"",H25,IF(D25="","",ROUND('Tech budget'!$B$5*'Tech budget'!$B$6^(B25-1),0))) | K25: =IF(J25<>"",J25,IF(D25="","",ROUND('Tech budget'!$B$7*'Tech budget'!$B$8^(B25-1),0)))
A26: Trade | B26: 1 | C26: 1 | E26: New gear | I26: =IF(H26<>"",H26,IF(D26="","",ROUND('Tech budget'!$B$5*'Tech budget'!$B$6^(B26-1),0))) | K26: =IF(J26<>"",J26,IF(D26="","",ROUND('Tech budget'!$B$7*'Tech budget'!$B$8^(B26-1),0)))
A27: Trade | B27: 1 | C27: 2 | I27: =IF(H27<>"",H27,IF(D27="","",ROUND('Tech budget'!$B$5*'Tech budget'!$B$6^(B27-1),0))) | K27: =IF(J27<>"",J27,IF(D27="","",ROUND('Tech budget'!$B$7*'Tech budget'!$B$8^(B27-1),0)))
A28: Trade | B28: 2 | C28: 1 | E28: Stat buff | I28: =IF(H28<>"",H28,IF(D28="","",ROUND('Tech budget'!$B$5*'Tech budget'!$B$6^(B28-1),0))) | K28: =IF(J28<>"",J28,IF(D28="","",ROUND('Tech budget'!$B$7*'Tech budget'!$B$8^(B28-1),0)))
A29: Trade | B29: 2 | C29: 2 | E29: Stat buff | I29: =IF(H29<>"",H29,IF(D29="","",ROUND('Tech budget'!$B$5*'Tech budget'!$B$6^(B29-1),0))) | K29: =IF(J29<>"",J29,IF(D29="","",ROUND('Tech budget'!$B$7*'Tech budget'!$B$8^(B29-1),0)))
A30: Trade | B30: 3 | C30: 1 | E30: New gear | I30: =IF(H30<>"",H30,IF(D30="","",ROUND('Tech budget'!$B$5*'Tech budget'!$B$6^(B30-1),0))) | K30: =IF(J30<>"",J30,IF(D30="","",ROUND('Tech budget'!$B$7*'Tech budget'!$B$8^(B30-1),0)))
A31: Trade | B31: 3 | C31: 2 | I31: =IF(H31<>"",H31,IF(D31="","",ROUND('Tech budget'!$B$5*'Tech budget'!$B$6^(B31-1),0))) | K31: =IF(J31<>"",J31,IF(D31="","",ROUND('Tech budget'!$B$7*'Tech budget'!$B$8^(B31-1),0)))
A32: Trade | B32: 4 | C32: 1 | E32: Stat buff | I32: =IF(H32<>"",H32,IF(D32="","",ROUND('Tech budget'!$B$5*'Tech budget'!$B$6^(B32-1),0))) | K32: =IF(J32<>"",J32,IF(D32="","",ROUND('Tech budget'!$B$7*'Tech budget'!$B$8^(B32-1),0)))
A33: Trade | B33: 4 | C33: 2 | E33: Stat buff | I33: =IF(H33<>"",H33,IF(D33="","",ROUND('Tech budget'!$B$5*'Tech budget'!$B$6^(B33-1),0))) | K33: =IF(J33<>"",J33,IF(D33="","",ROUND('Tech budget'!$B$7*'Tech budget'!$B$8^(B33-1),0)))
A34: Trade | B34: 5 | C34: 1 | E34: New gear | I34: =IF(H34<>"",H34,IF(D34="","",ROUND('Tech budget'!$B$5*'Tech budget'!$B$6^(B34-1),0))) | K34: =IF(J34<>"",J34,IF(D34="","",ROUND('Tech budget'!$B$7*'Tech budget'!$B$8^(B34-1),0)))
A35: Trade | B35: 5 | C35: 2 | I35: =IF(H35<>"",H35,IF(D35="","",ROUND('Tech budget'!$B$5*'Tech budget'!$B$6^(B35-1),0))) | K35: =IF(J35<>"",J35,IF(D35="","",ROUND('Tech budget'!$B$7*'Tech budget'!$B$8^(B35-1),0)))
A36: Trade | B36: 6 | C36: 1 | E36: Stat buff | I36: =IF(H36<>"",H36,IF(D36="","",ROUND('Tech budget'!$B$5*'Tech budget'!$B$6^(B36-1),0))) | K36: =IF(J36<>"",J36,IF(D36="","",ROUND('Tech budget'!$B$7*'Tech budget'!$B$8^(B36-1),0)))
A37: Trade | B37: 6 | C37: 2 | E37: Stat buff | I37: =IF(H37<>"",H37,IF(D37="","",ROUND('Tech budget'!$B$5*'Tech budget'!$B$6^(B37-1),0))) | K37: =IF(J37<>"",J37,IF(D37="","",ROUND('Tech budget'!$B$7*'Tech budget'!$B$8^(B37-1),0)))
A38: Trade | B38: 7 | C38: 1 | E38: New gear | I38: =IF(H38<>"",H38,IF(D38="","",ROUND('Tech budget'!$B$5*'Tech budget'!$B$6^(B38-1),0))) | K38: =IF(J38<>"",J38,IF(D38="","",ROUND('Tech budget'!$B$7*'Tech budget'!$B$8^(B38-1),0)))
A39: Trade | B39: 7 | C39: 2 | I39: =IF(H39<>"",H39,IF(D39="","",ROUND('Tech budget'!$B$5*'Tech budget'!$B$6^(B39-1),0))) | K39: =IF(J39<>"",J39,IF(D39="","",ROUND('Tech budget'!$B$7*'Tech budget'!$B$8^(B39-1),0)))
A40: Trade | B40: 8 | C40: 1 | E40: Stat buff | I40: =IF(H40<>"",H40,IF(D40="","",ROUND('Tech budget'!$B$5*'Tech budget'!$B$6^(B40-1),0))) | K40: =IF(J40<>"",J40,IF(D40="","",ROUND('Tech budget'!$B$7*'Tech budget'!$B$8^(B40-1),0)))
...

Sheet Tech budget
A1: Tech budget
A2: Yellow cells are yours to change. Everything else updates on its own.
A4: COST SETTINGS
A5: Research cost at level 1 | B5: 100 | F5: Research points for a level 1 unlock
A6: Research cost growth per level | B6: 1.25 | F6: 1.25 means each level costs 25% more than the last
A7: Strength needed at level 1 | B7: 10 | F7: Strength points in that track needed for a level 1 unlock
A8: Strength growth per level | B8: 1.3 | F8: Same idea, for the strength threshold
A11: UNLOCK BUDGET PER TRACK
A12: Track | B12: New gear target | C12: New gear used | D12: Stat buff target | E12: Stat buff used | F12: Status
A13: Military | B13: 6 | C13: =COUNTIFS(Tech!$A:$A,$A13,Tech!$F:$F,"New gear") -> 0 | D13: 12 | E13: =COUNTIFS(Tech!$A:$A,$A13,Tech!$F:$F,"Stat buff") -> 0 | F13: =IF(AND(C13=B13,E13=D13),"On budget",IF(OR(C13>B13,E13>D13),"Over budget","Room left: "&(B13-C13)&" gear, "&(D13-E13)&" buffs")) -> Room left: 6 gear, 12 buffs
A14: Trade | B14: 6 | C14: =COUNTIFS(Tech!$A:$A,$A14,Tech!$F:$F,"New gear") -> 0 | D14: 12 | E14: =COUNTIFS(Tech!$A:$A,$A14,Tech!$F:$F,"Stat buff") -> 0 | F14: =IF(AND(C14=B14,E14=D14),"On budget",IF(OR(C14>B14,E14>D14),"Over budget","Room left: "&(B14-C14)&" gear, "&(D14-E14)&" buffs")) -> Room left: 6 gear, 12 buffs
A15: Logistics | B15: 6 | C15: =COUNTIFS(Tech!$A:$A,$A15,Tech!$F:$F,"New gear") -> 0 | D15: 12 | E15: =COUNTIFS(Tech!$A:$A,$A15,Tech!$F:$F,"Stat buff") -> 0 | F15: =IF(AND(C15=B15,E15=D15),"On budget",IF(OR(C15>B15,E15>D15),"Over budget","Room left: "&(B15-C15)&" gear, "&(D15-E15)&" buffs")) -> Room left: 6 gear, 12 buffs
A16: Diplomacy | B16: 6 | C16: =COUNTIFS(Tech!$A:$A,$A16,Tech!$F:$F,"New gear") -> 0 | D16: 12 | E16: =COUNTIFS(Tech!$A:$A,$A16,Tech!$F:$F,"Stat buff") -> 0 | F16: =IF(AND(C16=B16,E16=D16),"On budget",IF(OR(C16>B16,E16>D16),"Over budget","Room left: "&(B16-C16)&" gear, "&(D16-E16)&" buffs")) -> Room left: 6 gear, 12 buffs
A17: Total | B17: =SUM(B13:B16) -> 24 | C17: =SUM(C13:C16) -> 0 | D17: =SUM(D13:D16) -> 48 | E17: =SUM(E13:E16) -> 0
A19: WHY THIS SPLIT
A20: 18 unlocks per track (12 levels, about 1.5 unlocks each), 72 in total.
A21: One third new gear (a hull, treaty type, building, unit) and two thirds stat buffs (armor tier, faster refuel, longer range).
A22: New gear is what adds things to design, draw, and balance, so it is the number to protect. Buffs are cheap to add or cut.
A23: Suggested rhythm: new gear on odd levels, buffs on even levels and in second slots. The Suggested type column on the Tech tab follows this; ignore it freely.

Sheet Art specs
A1: Asset | B1: Where it appears | C1: Size in pixels (recommended) | D1: Frames / variants | E1: How many for version 1 | F1: Notes | G1: Made by
A2: GLOBAL RULES | F2: PNG, transparent background, no anti-aliasing, no soft edges. Every size is a multiple of 8. Only colors from the master palette. Glow is added by the game, not drawn in. Image-generator output is never pixel-exact, so every generated image goes through cleanup (shrunk to target size with hard edges, every pixel snapped to the master palette, background removed) before review.
A3: Screen assumption | B3: Everything | C3: about 200 px wide | F3: The game draws at a small internal size and scales it up in whole steps, so one art pixel shows as a crisp 5 to 6 pixel block. A 64 px sprite is about a third of the screen width. The coding session confirms the exact number. Ships use a 3/4 view at higher resolution; modern feel comes from game-added lighting, glow, particles, trails and depth layers.
A4: Master palette | B4: Everything | C4: 1 swatch strip | D4: 32 to 48 colors | E4: 1 | F4: You choose every color. Include a 4-shade magenta ramp as the faction color slot: any pixel painted in those magenta shades is recolored per faction automatically. Magenta is used because it never appears in normal art. | G4: Owner
A5: Planet, system view | B5: Star system screen | C5: 16 / 24 / 32 (small / medium / large) | D5: Surface strip twice as wide as tall (e.g. 64x32) + optional cloud strip | E5: 1 per planet type | F5: Game scrolls the strip behind a circle to make it spin, and adds the night-side shadow. | G5: Owner
A6: Planet, detail view | B6: Planet screen | C6: 128 x 128 | D6: Surface strip 256 x 128 + cloud strip | E6: 1 per planet type | F6: Same method at higher detail. | G6: Owner
A7: Star | B7: Star system screen | C7: 48 or 64 | D7: 4 to 8 frames, or palette-cycling shades marked | E7: 1 per star type | F7: Corona animation can come from palette cycling instead of extra frames. | G7: Owner
A8: Black hole / special galaxy object | B8: Galaxy map + its system | C8: 48 or 64 | D8: 6 to 8 frames for accretion disk | E8: 3 to 4 types | F8: Lensing effect added by the game. | G8: Owner
A9: Point of interest | B9: Star system screen | C9: 16 or 24 | D9: 1 to 2 frames | E9: 4 to 6 types | F9: Dwarf planet, rogue moon, comet, derelict, etc. Asteroid belt is a tile set: 3 to 4 rock sprites at 8 x 8 scattered along a ring. | G9: Owner
A10: Elite ship, in-play sprite | B10: Star system view, battles | C10: 64 x 64 (capital ships up to 96 x 96) | D10: 3 drawn: side-on, angled toward camera, angled away. Game mirrors each for 6 angles | E10: 3 classes (carrier, dreadnought, capital ship) x species | F10: 3/4 view. Light from the upper left, consistent on every ship so mirroring stays believable. Faction markings in the magenta ramp. Lighting, glow, trails and shield effects are added by the game. | G10: Owner
A11: Elite ship, showcase | B11: Construction and purchase screens, ship screen, memorial, anywhere outside live play | C11: 256 x 144 (16:9) | D11: 1 still | E11: 3 classes x species | F11: Three-quarter angle, higher detail. Must match the top-down sprite's design, so attach the approved sprite as a reference when generating. | G11: Owner
A12: Battle and trade ship showcase (optional) | B12: Construction screen | C12: 128 x 72 (16:9) | D12: 1 still | E12: Optional for version 1 | F12: Same three-quarter treatment as capital ships, at smaller size. | G12: Owner
A13: Corvette | B13: Fleets, escorts | C13: 32 x 32 | D13: 3 drawn, mirrored for 6 angles | E13: 1 class x species | F13: 3/4 view, same angles and lighting as elite ships. No hangar. | G13: Owner
A14: Fighter and bomber | B14: Battles, fleet panels | C14: 16 x 16 | D14: 1 drawn, seen from above; the game rotates it freely with a motion trail | E14: 2 classes x species | F14: Tiny enough that free rotation reads fine. Stored in carriers, dreadnoughts and capital ships. Battles draw a representative swarm. | G14: Owner
A15: Trade ship | B15: Lanes between trade hubs, battles (tankers) | C15: 32 x 32 (merchant, cargo) / 48 x 48 (freighter, tanker) | D15: 2 drawn: side-on and angled toward camera, mirrored | E15: 4 classes (merchant vessel, cargo ship, freighter, tanker) x species, or one shared civilian set | F15: Unarmed civilian look. Tankers must read clearly as tankers, since enemies target them in battle. | G15: Owner
... A20: Emblem parts | B20: Faction emblems | C20: 32 x 32 | D20: Shapes, borders, symbols as separate layers | E20: 8 to 12 of each | F20: The game combines your parts into each faction's emblem. | G20: Owner (to confirm)
A21: Galaxy map node icons | B21: Galaxy map | C21: 16 x 16 | D21: 1 to 2 frames | E21: Owned, contested, neutral, special | G21: Claude (coding)
A22: Interface icons | B22: Menus, resources | C22: 16 x 16 | D22: 1 | E22: ~40 | F22: Resources, advisors, actions. | G22: Claude (coding)
A23: Bitmap font | B23: All text | C23: glyphs 5 x 7 or 6 x 8 | D23: Full character set | E23: 1 to 2 fonts | F23: Can start from a CC0 pixel font and be swapped later. | G23: Claude (coding)
A24: FILE NAMING | F24: type_species_culture_name_size.png, e.g. capital_ploidun_orr_dreadnought_32.png. Animation frames go in one horizontal strip, equal cells.
A25: Effects | B25: Battles, star system view | C25: varies | D25: Particles, glow, trails, explosions, shield shimmer | E25: As needed | F25: Made in code to fit the palette and style | G25: Claude (coding)
A26: Menus and screen layouts | B26: Everywhere | C26: fits the screen assumption | E26: All screens | F26: Hologram style, amber for the player's interface | G26: Claude (coding)
A27: Backgrounds | B27: Galaxy map, star systems, battles | C27: Full screen, tiling | D27: Parallax layers | E27: As needed | F27: Prompt template available if the owner wants to supply these instead | G27: Claude (coding)

Sheet Prompt templates
A1: Asset type | B1: Final game size | C1: Generate at | D1: Prompt template | E1: Fill in | F1: Attach as reference | G1: Cleanup before review
A2: HOW TO USE | D2: Copy a template, replace every [BRACKETED] part, and attach the listed references. Always attach the master palette swatch so colors stay consistent across the whole game. Keep the fixed wording as is: it is what makes separate images match each other.
A3: Planet surface strip | B3: 64 x 32 or 256 x 128 | C3: 1536 x 1024, crop to 2:1 | D3: Seamless horizontally tiling planet surface texture map in flat equirectangular projection, filling the full width of the image in a 2:1 band. [PLANET TYPE AND TERRAIN]. Drawn only in [SHADING RAMPS], with no lighting, no shadows, no sphere and no background. The left and right edges must match exactly so the texture wraps around. pixel art with crisp hard-edged square pixels, no anti-aliasing, no blur, no gradients, no text, limited palette matching the attached swatch. | E3: PLANET TYPE AND TERRAIN (e.g. volcanic world with lava rivers and black basalt plains); SHADING RAMPS (e.g. four gray shades for land and three for lava) | F3: Palette swatch; an approved strip for consistency | G3: Shrink to final size with hard edges, snap to master palette, remove background; confirm left and right edges join
A4: Planet cloud layer | B4: Matches its surface strip | C4: 1536 x 1024, crop to 2:1 | D4: Seamless horizontally tiling cloud layer in flat equirectangular projection, filling a 2:1 band. [CLOUD STYLE] in white and pale gray on a fully transparent background. The left and right edges must match exactly. pixel art with crisp hard-edged square pixels, no anti-aliasing, no blur, no gradients, no text, limited palette matching the attached swatch. | E4: CLOUD STYLE (e.g. thin wispy bands, scattered storm cells, dense toxic haze) | F4: Palette swatch | G4: Shrink to final size with hard edges, snap to master palette, remove background; confirm edges join
A5: Planet showcase | B5: Menus and loading screens | C5: 1024 x 1024 | D5: A [PLANET TYPE] planet seen from space, lit from the [LIGHT DIRECTION], with a thin glowing atmosphere ring in [ATMOSPHERE COLOR], against near-black navy space with sparse distant stars. Centered, full sphere visible. pixel art with crisp hard-edged square pixels, no anti-aliasing, no blur, no gradients, no text, limited palette matching the attached swatch. | E5: PLANET TYPE; LIGHT DIRECTION (e.g. upper left); ATMOSPHERE COLOR | F5: Palette swatch; the planet's approved surface strip | G5: Shrink to final size with hard edges, snap to master palette, remove background
A6: Star | B6: 48 or 64 | C6: 1024 x 1024 | D6: A [STAR TYPE] star seen front-on, centered, with a bright core and a ragged corona in [CORONA COLORS], on a transparent background. No lens flare. pixel art with crisp hard-edged square pixels, no anti-aliasing, no blur, no gradients, no text, limited palette matching the attached swatch. | E6: STAR TYPE (e.g. red dwarf, blue giant, white dwarf); CORONA COLORS | F6: Palette swatch | G6: Shrink to final size with hard edges, snap to master palette, remove background
A7: Special galaxy object | B7: 48 or 64 | C7: 1024 x 1024 | D7: A [OBJECT] seen from above at a slight tilt, centered, with its glow drawn as hard-edged bands of [GLOW COLORS], on a transparent background. pixel art with crisp hard-edged square pixels, no anti-aliasing, no blur, no gradients, no text, limited palette matching the attached swatch. | E7: OBJECT (e.g. black hole with a glowing accretion disk, pulsar with twin beams, supernova remnant cloud); GLOW COLORS | F7: Palette swatch | G7: Shrink to final size with hard edges, snap to master palette, remove background
A8: Point of interest | B8: 16 or 24 | C8: 1024 x 1024 | D8: A small [POINT OF INTEREST] seen from above, simple and readable at very small size, centered on a transparent background. [STYLE NOTES]. pixel art with crisp hard-edged square pixels, no anti-aliasing, no blur, no gradients, no text, limited palette matching the attached swatch. | E8: POINT OF INTEREST (e.g. derelict station, icy comet with a short tail, cratered rogue moon, dwarf planet); STYLE NOTES (species and culture style if it was built by someone) | F8: Palette swatch | G8: Shrink to final size with hard edges, snap to master palette, remove background
A9: Asteroid tiles | B9: 8 x 8 each | C9: 1536 x 1024 | D9: A sprite sheet of four small asteroids seen from directly above, irregular rocky shapes in [ROCK COLORS], all the same size, evenly spaced in one row on a transparent background. pixel art with crisp hard-edged square pixels, no anti-aliasing, no blur, no gradients, no text, limited palette matching the attached swatch. | E9: ROCK COLORS | F9: Palette swatch | G9: Shrink to final size with hard edges, snap to master palette, remove background; split into four files
A10: Ship, side-on sprite | B10: 64 x 64 (elite), 32 x 32 (corvette, trade), 24 x 24 (scout) | C10: 1024 x 1024 | D10: A [SHIP CLASS] starship in a three-quarter view seen from the side, nose pointing right, lit from the upper left. Built by the [SPECIES] in [CULTURE] style: [SHAPE LANGUAGE]. Hull in [HULL COLORS]. All faction markings and running lights painted only in four shades of pure magenta so they can be recolored. Detailed but with a strong, readable silhouette. Centered on a transparent background, no engine glow or effects. pixel art with crisp hard-edged square pixels, no anti-aliasing, no blur, no gradients, no text, limited palette matching the attached swatch. | E10: SHIP CLASS (carrier, dreadnought, capital ship, corvette, scout, merchant vessel, cargo ship, freighter, liquid tanker); SPECIES; CULTURE; SHAPE LANGUAGE (civilian and unarmed for trade ships); HULL COLORS | F10: Palette swatch; another approved ship of the same species for family resemblance | G10: Shrink to final size with hard edges, snap to palette, remove background; check magenta markings survived
A11: Ship, angled sprites | B11: Same as side-on | C11: 1024 x 1024 | D11: The exact same starship as the attached reference, unchanged in design and lighting (lit from the upper left), now turned [ANGLE]. Three-quarter view, magenta faction markings kept, no engine glow or effects, transparent background. pixel art with crisp hard-edged square pixels, no anti-aliasing, no blur, no gradients, no text, limited palette matching the attached swatch. | E11: ANGLE: 'about 45 degrees toward the viewer, nose pointing lower right' or 'about 45 degrees away from the viewer, nose pointing upper right'. Trade ships and scouts need only the first | F11: The approved side-on sprite (required) | G11: Shrink to final size with hard edges, snap to master palette, remove background; compare against nose-up version
A12: Elite ship, showcase | B12: 256 x 144 | C12: 1536 x 1024 | D12: The starship from the attached reference shown at a dramatic three-quarter angle from slightly above, same design and proportions. [SPECIES] [CULTURE] construction: [SHAPE LANGUAGE]. Hull in [HULL COLORS], faction markings in [FACTION COLORS], engines glowing [ENGINE COLOR]. Set against near-black navy space with a faint [NEBULA COLOR] nebula. Cinematic but clean, with detail visible as pixels. pixel art with crisp hard-edged square pixels, no anti-aliasing, no blur, no gradients, no text, limited palette matching the attached swatch. | E12: SPECIES; CULTURE; SHAPE LANGUAGE; HULL COLORS; FACTION COLORS; ENGINE COLOR; NEBULA COLOR | F12: The approved top-down sprite (required); palette swatch | G12: Shrink to 256 x 144 with hard edges, snap to palette
A13: Fighter or bomber | B13: 16 x 16 | C13: 1024 x 1024 | D13: A tiny [ROLE] spacecraft seen from directly above, nose pointing up, an extremely simple shape whose role is obvious from its silhouette: [SILHOUETTE NOTE]. [SPECIES] style, hull in [HULL COLORS], one magenta accent. No engine glow. Transparent background. pixel art with crisp hard-edged square pixels, no anti-aliasing, no blur, no gradients, no text, limited palette matching the attached swatch. | E13: ROLE (fighter or bomber); SILHOUETTE NOTE (fighter slim and pointed, bomber wide and heavy); SPECIES; HULL COLORS | F13: Palette swatch; the species' approved escort | G13: Shrink to final size with hard edges, snap to master palette, remove background
A14: Ground regiment icon | B14: 16 x 16 | C14: 1024 x 1024 | D14: An emblem-like icon of a [REGIMENT TYPE] regiment, a tight group of figures or vehicles, seen from [VIEW], small and instantly readable, [SPECIES] [CULTURE] equipment style, faction accents in four shades of pure magenta, centered on a transparent background. pixel art with crisp hard-edged square pixels, no anti-aliasing, no blur, no gradients, no text, limited palette matching the attached swatch. | E14: REGIMENT TYPE (infantry, armor, mercy healers, heavies); VIEW (top-down or side, pick one for all); SPECIES; CULTURE | F14: Palette swatch; another approved unit | G14: Shrink to final size with hard edges, snap to master palette, remove background
... A22: Background layer | B22: Full screen, tiling | C22: 1024 x 1536 | D22: A seamless tiling space background layer of [LAYER CONTENT] on near-black navy, edges matching on all four sides so it can repeat. pixel art with crisp hard-edged square pixels, no anti-aliasing, no blur, no gradients, no text, limited palette matching the attached swatch. | E22: LAYER CONTENT (e.g. sparse distant stars only, soft [COLOR] nebula clouds) | F22: Palette swatch | G22: Snap to palette; confirm it tiles

Sheet Asset list
A1: Asset name | B1: Type (from Art specs) | C1: Species | D1: Culture | E1: Size | F1: Frames | G1: Status | H1: File name | I1: Notes
A2: Dreadnought (example) | B2: Capital ship, map sprite | C2: Ploidun | D2: Orr (example) | E2: 32 x 32 | F2: 5 | G2: placeholder | H2: capital_ploidun_orr_dreadnought_32.png

Sheet Audio list
A1: Slot name | B1: Where it plays | C1: Type | D1: Loops (Y/N) | E1: Target length | F1: File name | G1: Status | H1: Notes
A2: FORMAT | H2: MP3 or M4A for the widest iPhone support. Loops should start and end cleanly with no silence gap. Keep effects short (under 2 seconds). The game plays nothing until the player's first tap; iPhones require that.
A3: music_galaxy_map | B3: Galaxy map | C3: music | D3: Y | E3: 2 to 4 min | F3: music_galaxy_map.mp3 | G3: placeholder
A4: music_system_view | B4: Star system screen | C4: music | D4: Y | E4: 2 to 4 min | F4: music_system_view.mp3 | G4: placeholder | H4: Main ambient track; players spend the most time here
A5: music_battle | B5: Battles in progress | C5: music | D5: Y | E5: 1 to 3 min | F5: music_battle.mp3 | G5: placeholder
A6: music_victory | B6: Campaign won | C6: music | D6: N | E6: 30 to 60 sec | G6: placeholder
A7: music_defeat | B7: Campaign lost | C7: music | D7: N | E7: 30 to 60 sec | G7: placeholder
A8: ambience_space | B8: Under the music everywhere | C8: ambience | D8: Y | E8: 1 to 2 min | G8: placeholder | H8: Low hum, distant radio chatter
A9: ambience_black_hole | B9: Black hole systems | C9: ambience | D9: Y | E9: 1 min | G9: placeholder
A10: sfx_tap | B10: Every button | C10: effect | D10: N | E10: under 0.2 sec | G10: placeholder
A11: sfx_alert | B11: Incoming attack, capital ship disabled | C11: effect | D11: N | E11: under 1 sec | G11: placeholder
A12: sfx_advisor | B12: New advisor request | C12: effect | D12: N | E12: under 1 sec | G12: placeholder | H12: Could vary per advisor
A13: sfx_build_complete | B13: Construction finished | C13: effect | D13: N | E13: under 1 sec | G13: placeholder
A14: sfx_treaty | B14: Treaty signed or broken | C14: effect | D14: N | E14: under 1 sec | G14: placeholder
A15: sfx_retreat | B15: Retreat ordered | C15: effect | D15: N | E15: under 1 sec | G15: placeholder
A16: sfx_memorial | B16: Commander's sendoff | C16: effect | D16: N | E16: 2 to 4 sec | G16: placeholder
